Workbook

Sheet Daily Plan
A1: Date | B1: Day | C1: Day type | D1: Phase | E1: Unit | F1: Main topic or session | G1: Subtopics and session focus | H1: Paper scope | I1: Priority (CSE primary) | J1: Daily routine (CSE-first allocation) | K1: Theory done | L1: Previous-year questions done | M1: Revision done | N1: Recall test and mistake review done | O1: Unit complete | P1: Actual hours | Q1: Previous-year question accuracy (fraction) | R1: Mistakes and next action
A2: 46318 | B2: Friday | C2: Study session | D2: Phase 1: CSE/shared priority — programming, data structures and algorithms (Part 1) | E2: Unit 28 | F2: Programming 1: C and Python Fundamentals — Session A (C) | G2: Computer Science (C language): C variables, control flow, functions, recursion Session focus: Part A (23 Oct, plan start): C fundamentals - data types, operators, control flow, functions and recursion; CSE PYQs first. | H2: Computer Science (C language) and Data Science and Artificial Intelligence (Python) | I2: Tier 1 – CSE/shared must master | J2: CSE/shared day (6.5–8 focused hours): 3–4 hours concepts and worked examples; 1.5–2 hours CSE PYQs first; 30–45 minutes DA-style variants where the topic overlaps; 20–30 minutes General Aptitude; 20 minutes spaced foundation recall; 15–20 minutes mistake log and recall quiz. | K2: No | L2: No | M2: No | N2: No | O2: =IF(COUNTIF(K2:N2,"Yes")=4,"Complete","Not yet complete") -> Not yet complete
A3: 46319 | B3: Saturday | C3: Study session | D3: Phase 1: CSE/shared priority — programming, data structures and algorithms (Part 1) | E3: Unit 28 | F3: Programming 1: C and Python Fundamentals — Session B (Python) | G3: Data Science and Artificial Intelligence only: Python syntax, data types, control structures, functions Session focus: Part B (24 Oct): Python fundamentals, DA-style PYQs, plus C recursion/tracing revision from Session A. | H3: Computer Science (C language) and Data Science and Artificial Intelligence (Python) | I3: Tier 1 – CSE/shared must master | J3: CSE/shared day (6.5–8 focused hours): 3–4 hours concepts and worked examples; 1.5–2 hours CSE PYQs first; 30–45 minutes DA-style variants where the topic overlaps; 20–30 minutes General Aptitude; 20 minutes spaced foundation recall; 15–20 minutes mistake log and recall quiz. | K3: No | L3: No | M3: No | N3: No | O3: =IF(COUNTIF(K3:N3,"Yes")=4,"Complete","Not yet complete") -> Not yet complete
A4: 46320 | B4: Sunday | C4: Timed test or diagnostic | D4: Weekly catch-up | E4: Sunday review 1 | F4: Foundation diagnostic 1: Linear algebra and discrete mathematics | G4: Timed set of about 25 previous-year questions (90 minutes) covering linear algebra and discrete mathematics, including logic and graph theory. Any topic scoring below 70 percent goes onto the January second-pass list. | H4: Both papers | I4: Consolidation | J4: 3-hour timed or 90-minute diagnostic attempt; deep analysis; update the mistake log; queue weak topics for repair. | K4: No | L4: No | M4: No | N4: No | O4: =IF(COUNTIF(K4:N4,"Yes")=4,"Complete","Not yet complete") -> Not yet complete
A5: 46321 | B5: Monday | C5: Study session | D5: Phase 1: CSE/shared priority — programming, data structures and algorithms (Part 1) | E5: Unit 29 | F5: Programming 2: Memory, Pointers and Code Tracing | G5: Computer Science (C language): C pointers, arrays, strings, storage classes and output/code tracing; C uses lexical/static scope. Do not spend core syllabus time treating dynamic scoping as a C feature. | Data Science and Artificial Intelligence (Python): lists, dictionaries, slicing and tracing program output | H5: Computer Science (C language) and Data Science and Artificial Intelligence (Python) | I5: Tier 1 – CSE/shared must master | J5: CSE/shared day (6.5–8 focused hours): 3–4 hours concepts and worked examples; 1.5–2 hours CSE PYQs first; 30–45 minutes DA-style variants where the topic overlaps; 20–30 minutes General Aptitude; 20 minutes spaced foundation recall; 15–20 minutes mistake log and recall quiz. | K5: No | L5: No | M5: No | N5: No | O5: =IF(COUNTIF(K5:N5,"Yes")=4,"Complete","Not yet complete") -> Not yet complete
A6: 46322 | B6: Tuesday | C6: Study session | D6: Phase 1: CSE/shared priority — programming, data structures and algorithms (Part 1) | E6: Unit 30 | F6: Data Structures 1: Arrays, Stacks and Queues | G6: Both papers: one-dimensional and two-dimensional array addressing, Stacks (infix/postfix, recursion stack), Queues (circular, priority queue basics) | H6: Shared by both papers | I6: Tier 1 – CSE/shared must master | J6: CSE/shared day (6.5–8 focused hours): 3–4 hours concepts and worked examples; 1.5–2 hours CSE PYQs first; 30–45 minutes DA-style variants where the topic overlaps; 20–30 minutes General Aptitude; 20 minutes spaced foundation recall; 15–20 minutes mistake log and recall quiz. | K6: No | L6: No | M6: No | N6: No | O6: =IF(COUNTIF(K6:N6,"Yes")=4,"Complete","Not yet complete") -> Not yet complete
A7: 46323 | B7: Wednesday | C7: Study session | D7: Phase 1: CSE/shared priority — programming, data structures and algorithms (Part 1) | E7: Unit 31 | F7: Data Structures 2: Linked Lists | G7: Both papers: Singly, doubly, and circular linked lists; pointer manipulation and complexity in C and Python | H7: Shared by both papers | I7: Tier 1 – CSE/shared must master | J7: CSE/shared day (6.5–8 focused hours): 3–4 hours concepts and worked examples; 1.5–2 hours CSE PYQs first; 30–45 minutes DA-style variants where the topic overlaps; 20–30 minutes General Aptitude; 20 minutes spaced foundation recall; 15–20 minutes mistake log and recall quiz. | K7: No | L7: No | M7: No | N7: No | O7: =IF(COUNTIF(K7:N7,"Yes")=4,"Complete","Not yet complete") -> Not yet complete
A8: 46324 | B8: Thursday | C8: Study session | D8: Phase 1: CSE/shared priority — programming, data structures and algorithms (Part 1) | E8: Unit 32 | F8: Data Structures 3: Trees, Binary Search Trees and Heaps | G8: Both papers: Binary trees, tree traversals, Binary Search Trees, AVL rotations | Computer Science core: Binary heaps, heapify, priority queues | H8: Shared by both papers plus Computer Science core | I8: Tier 1 – CSE/shared must master | J8: CSE/shared day (6.5–8 focused hours): 3–4 hours concepts and worked examples; 1.5–2 hours CSE PYQs first; 30–45 minutes DA-style variants where the topic overlaps; 20–30 minutes General Aptitude; 20 minutes spaced foundation recall; 15–20 minutes mistake log and recall quiz. | K8: No | L8: No | M8: No | N8: No | O8: =IF(COUNTIF(K8:N8,"Yes")=4,"Complete","Not yet complete") -> Not yet complete
A9: 46325 | B9: Friday | C9: Study session | D9: Phase 1: CSE/shared priority — programming, data structures and algorithms (Part 1) | E9: Unit 33 | F9: Data Structures 4: Hash Tables | G9: Both papers: Hash functions, collision resolution (chaining, open addressing: linear/quadratic probing, double hashing), load factor | H9: Shared by both papers | I9: Tier 1 – CSE/shared must master | J9: CSE/shared day (6.5–8 focused hours): 3–4 hours concepts and worked examples; 1.5–2 hours CSE PYQs first; 30–45 minutes DA-style variants where the topic overlaps; 20–30 minutes General Aptitude; 20 minutes spaced foundation recall; 15–20 minutes mistake log and recall quiz. | K9: No | L9: No | M9: No | N9: No | O9: =IF(COUNTIF(K9:N9,"Yes")=4,"Complete","Not yet complete") -> Not yet complete
A10: 46326 | B10: Saturday | C10: Study session | D10: Phase 1: CSE/shared priority — programming, data structures and algorithms (Part 1) | E10: Unit 34 | F10: Algorithms 1: Asymptotic Analysis and Recurrences | G10: Both papers: Big-O, Omega, Theta notations, time and space complexity | Computer Science core: Solving recurrences (Substitution, Tree, Master Theorem) | H10: Shared by both papers plus Computer Science core | I10: Tier 1 – CSE/shared must master | J10: CSE/shared day (6.5–8 focused hours): 3–4 hours concepts and worked examples; 1.5–2 hours CSE PYQs first; 30–45 minutes DA-style variants where the topic overlaps; 20–30 minutes General Aptitude; 20 minutes spaced foundation recall; 15–20 minutes mistake log and recall quiz. | K10: No | L10: No | M10: No | N10: No | O10: =IF(COUNTIF(K10:N10,"Yes")=4,"Complete","Not yet complete") -> Not yet complete
A11: 46327 | B11: Sunday | C11: Timed test or diagnostic | D11: Weekly catch-up | E11: Sunday review 2 | F11: Foundation diagnostic 2: Calculus, probability and statistics | G11: Timed set of about 25 previous-year questions (90 minutes) covering calculus, probability, and statistics (central limit theorem, confidence intervals, hypothesis tests). Any topic scoring below 70 percent goes onto the January second-pass list. | H11: Both papers | I11: Consolidation | J11: 3-hour timed or 90-minute diagnostic attempt; deep analysis; update the mistake log; queue weak topics for repair. | K11: No | L11: No | M11: No | N11: No | O11: =IF(COUNTIF(K11:N11,"Yes")=4,"Complete","Not yet complete") -> Not yet complete
A12: 46328 | B12: Monday | C12: Study session | D12: Phase 1: CSE/shared priority — programming, data structures and algorithms (Part 1) | E12: Unit 35 | F12: Algorithms 2: Searching and Simple Sorting | G12: Both papers: Linear search, binary search, selection sort, bubble sort, insertion sort (stability and in-place analysis) | H12: Shared by both papers | I12: Tier 1 – CSE/shared must master | J12: CSE/shared day (6.5–8 focused hours): 3–4 hours concepts and worked examples; 1.5–2 hours CSE PYQs first; 30–45 minutes DA-style variants where the topic overlaps; 20–30 minutes General Aptitude; 20 minutes spaced foundation recall; 15–20 minutes mistake log and recall quiz. | K12: No | L12: No | M12: No | N12: No | O12: =IF(COUNTIF(K12:N12,"Yes")=4,"Complete","Not yet complete") -> Not yet complete
A13: 46329 | B13: Tuesday | C13: Study session | D13: Phase 1: CSE/shared priority — programming, data structures and algorithms (Part 1) | E13: Unit 36 | F13: Algorithms 3: Divide and Conquer | G13: Both papers: Merge sort, Quick sort | Computer Science core: Counting inversions, min-max, recurrence-based divide and conquer design | H13: Shared by both papers plus Computer Science core | I13: Tier 1 – CSE/shared must master | J13: CSE/shared day (6.5–8 focused hours): 3–4 hours concepts and worked examples; 1.5–2 hours CSE PYQs first; 30–45 minutes DA-style variants where the topic overlaps; 20–30 minutes General Aptitude; 20 minutes spaced foundation recall; 15–20 minutes mistake log and recall quiz. | K13: No | L13: No | M13: No | N13: No | O13: =IF(COUNTIF(K13:N13,"Yes")=4,"Complete","Not yet complete") -> Not yet complete
... A107: 46423 | B107: Friday | C107: Final taper | D107: Phase 8: Final taper | E107: Taper 3 | F107: Rest day before the first exam window | G107: Rest. Confirm your own exam date and session on the official portal. No new material. | H107: Both papers | I107: Exam runway | J107: Rest; light walk; early night. | K107: No | L107: No | M107: No | N107: No | O107: =IF(COUNTIF(K107:N107,"Yes")=4,"Complete","Not yet complete") -> Not yet complete

Sheet Rules and Sequence
A1: Rule | B1: Decision
A2: Core rule | B2: Computer Science (CSE) is the primary paper. CSE-only and genuinely shared topics are Tier 1 and receive the first claim on study and PYQ time. Data Science and Artificial Intelligence (DA) only topics remain required, but are Tier 2 and do not displace CSE practice.
A3: Starting point | B3: Units 1–17 (logic, discrete mathematics, linear algebra, calculus, probability and statistics) are recorded as completed, as stated on 23 October 2026. The revised calendar starts on 23 October (Programming 1 split into Session A on 23 Oct and Session B on 24 Oct) with CSE/shared programming and data structures, not the DA-only Machine Learning block.
A4: Study week | B4: The calendar now runs from 23 October 2026 to 5 February 2027; all dates from 24 October onward are unchanged. Sundays in the content phase remain catch-up/diagnostic days. The scheduled official DA papers are moved to 10, 17 and 24 January so all DA content is complete first.
A5: Sequence | B5: CSE/shared priority sequence: C and Python programming; data structures and algorithms; AI search immediately after graph algorithms; database core then DA data preparation/warehousing; Theory of Computation and compiler design; Digital Logic, Computer Organization, Operating Systems and Networks; finally DA uncertainty/Bayesian inference and Machine Learning. One main topic stream; no unrelated chapter switching.
A6: Content end dates | B6: CSE-specific content through Networks ends 21 December 2026. The final DA-only Bayesian uncertainty and Machine Learning block runs 22 December to 4 January 2027. All scheduled content ends 4 January; second pass remains 5–19 January; mock/repair phase 20 January–2 February; final taper 3–5 February.
A7: Completion rule | B7: Do not mark a unit complete because its date has passed. Set all four Yes/No completion checks (theory, previous-year questions, revision, recall/mistake review) to Yes; the Unit complete formula then shows Complete.
A8: Buffer rule | B8: If a session overruns, finish it on the next Sunday/catch-up slot or use 18 or 19 January for repair. 16 January is reserved for a Computer Networks sectional test. Add a third Networks session only if its sectional score is below 70%, Unit 69 is incomplete, or error analysis shows a material gap; use 18 or 19 January rather than adding a calendar day.
A9: Spaced revision | B9: Each study day keeps its existing spaced-revision structure: re-test earlier content after 1, 3, 7 and 21 study sessions. Sundays are not counted as new study sessions unless they hold an explicitly scheduled timed paper.
A10: Foundation upkeep | B10: Every day includes a short retrieval block from completed Units 1–17. During CSE-heavy weeks, use Tuesday, Thursday and Saturday for DA formula recall plus 3–5 starred questions; on DA-only days, the larger extra block is reserved for CSE foundation PYQs.
A11: Daily time budget | B11: CSE/shared days: approximately 6.5–8 hours, with 3–4 hours concepts, 1.5–2 hours CSE PYQs first, then DA-style variants where topics overlap, plus General Aptitude, spaced revision and mistake logging. DA-only days: cap new DA content at 3–3.5 hours, use 60–90 minutes for DA PYQs, then 1.5 hours for CSE foundation recall/PYQs, plus General Aptitude and spaced revision.
A12: Previous-year question rule | B12: Aim for 15–25 suitable questions only when authentic questions are available. Analyse fewer hard questions fully rather than rush. Use authentic official papers and answer keys; never substitute invented questions for unavailable papers.
... A17: Naming note | B17: Use the exact official 2027 syllabus, not generic or prior-year assumptions. Standard algorithm/parser names such as LL(1), LR(0), SLR(1), CLR(1), LALR(1), AVL, SCAN, C-SCAN and LOOK remain in their conventional form.

Sheet Phase Overview
A1: Phase | B1: First date | C1: Last date | D1: Total days | E1: Study sessions | F1: Days complete | G1: Percent complete
A2: Phase 1: CSE/shared priority — programming, data structures and algorithms (Part 1) | B2: =INDEX('Daily Plan'!$A$2:$A$107,MATCH(A2,'Daily Plan'!$D$2:$D$107,0)) -> 46318 | C2: =SUMPRODUCT(MAX(('Daily Plan'!$D$2:$D$107=A2)*'Daily Plan'!$A$2:$A$107)) -> 46332 | D2: =COUNTIFS('Daily Plan'!$D$2:$D$107,A2) -> 13 | E2: =COUNTIFS('Daily Plan'!$D$2:$D$107,A2,'Daily Plan'!$C$2:$C$107,"Study session") -> 13 | F2: =COUNTIFS('Daily Plan'!$D$2:$D$107,A2,'Daily Plan'!$O$2:$O$107,"Complete") -> 0 | G2: =IF(D2=0,0,F2/D2) -> 0
A3: Phase 2: Finish algorithms; AI search; databases/warehousing; begin Theory of Computation | B3: =INDEX('Daily Plan'!$A$2:$A$107,MATCH(A3,'Daily Plan'!$D$2:$D$107,0)) -> 46333 | C3: =SUMPRODUCT(MAX(('Daily Plan'!$D$2:$D$107=A3)*'Daily Plan'!$A$2:$A$107)) -> 46352 | D3: =COUNTIFS('Daily Plan'!$D$2:$D$107,A3) -> 17 | E3: =COUNTIFS('Daily Plan'!$D$2:$D$107,A3,'Daily Plan'!$C$2:$C$107,"Study session") -> 17 | F3: =COUNTIFS('Daily Plan'!$D$2:$D$107,A3,'Daily Plan'!$O$2:$O$107,"Complete") -> 0 | G3: =IF(D3=0,0,F3/D3) -> 0
A4: Phase 3: Theory of Computation and compilers; begin CSE systems | B4: =INDEX('Daily Plan'!$A$2:$A$107,MATCH(A4,'Daily Plan'!$D$2:$D$107,0)) -> 46353 | C4: =SUMPRODUCT(MAX(('Daily Plan'!$D$2:$D$107=A4)*'Daily Plan'!$A$2:$A$107)) -> 46364 | D4: =COUNTIFS('Daily Plan'!$D$2:$D$107,A4) -> 10 | E4: =COUNTIFS('Daily Plan'!$D$2:$D$107,A4,'Daily Plan'!$C$2:$C$107,"Study session") -> 10 | F4: =COUNTIFS('Daily Plan'!$D$2:$D$107,A4,'Daily Plan'!$O$2:$O$107,"Complete") -> 0 | G4: =IF(D4=0,0,F4/D4) -> 0
A5: Phase 4: Computer Organization and Operating Systems | B5: =INDEX('Daily Plan'!$A$2:$A$107,MATCH(A5,'Daily Plan'!$D$2:$D$107,0)) -> 46365 | C5: =SUMPRODUCT(MAX(('Daily Plan'!$D$2:$D$107=A5)*'Daily Plan'!$A$2:$A$107)) -> 46373 | D5: =COUNTIFS('Daily Plan'!$D$2:$D$107,A5) -> 8 | E5: =COUNTIFS('Daily Plan'!$D$2:$D$107,A5,'Daily Plan'!$C$2:$C$107,"Study session") -> 8 | F5: =COUNTIFS('Daily Plan'!$D$2:$D$107,A5,'Daily Plan'!$O$2:$O$107,"Complete") -> 0 | G5: =IF(D5=0,0,F5/D5) -> 0
A6: Phase 5: Finish CSE systems; DA uncertainty and Machine Learning (secondary) | B6: =INDEX('Daily Plan'!$A$2:$A$107,MATCH(A6,'Daily Plan'!$D$2:$D$107,0)) -> 46374 | C6: =SUMPRODUCT(MAX(('Daily Plan'!$D$2:$D$107=A6)*'Daily Plan'!$A$2:$A$107)) -> 46391 | D6: =COUNTIFS('Daily Plan'!$D$2:$D$107,A6) -> 15 | E6: =COUNTIFS('Daily Plan'!$D$2:$D$107,A6,'Daily Plan'!$C$2:$C$107,"Study session") -> 15 | F6: =COUNTIFS('Daily Plan'!$D$2:$D$107,A6,'Daily Plan'!$O$2:$O$107,"Complete") -> 0 | G6: =IF(D6=0,0,F6/D6) -> 0
A7: Phase 6: Second-pass revision and targeted repair | B7: =INDEX('Daily Plan'!$A$2:$A$107,MATCH(A7,'Daily Plan'!$D$2:$D$107,0)) -> 46392 | C7: =SUMPRODUCT(MAX(('Daily Plan'!$D$2:$D$107=A7)*'Daily Plan'!$A$2:$A$107)) -> 46406 | D7: =COUNTIFS('Daily Plan'!$D$2:$D$107,A7) -> 15 | E7: =COUNTIFS('Daily Plan'!$D$2:$D$107,A7,'Daily Plan'!$C$2:$C$107,"Study session") -> 0 | F7: =COUNTIFS('Daily Plan'!$D$2:$D$107,A7,'Daily Plan'!$O$2:$O$107,"Complete") -> 0 | G7: =IF(D7=0,0,F7/D7) -> 0
A8: Phase 7: CSE mocks, DA papers/sectionals and repair | B8: =INDEX('Daily Plan'!$A$2:$A$107,MATCH(A8,'Daily Plan'!$D$2:$D$107,0)) -> 46407 | C8: =SUMPRODUCT(MAX(('Daily Plan'!$D$2:$D$107=A8)*'Daily Plan'!$A$2:$A$107)) -> 46420 | D8: =COUNTIFS('Daily Plan'!$D$2:$D$107,A8) -> 14 | E8: =COUNTIFS('Daily Plan'!$D$2:$D$107,A8,'Daily Plan'!$C$2:$C$107,"Study session") -> 0 | F8: =COUNTIFS('Daily Plan'!$D$2:$D$107,A8,'Daily Plan'!$O$2:$O$107,"Complete") -> 0 | G8: =IF(D8=0,0,F8/D8) -> 0
A9: Phase 8: Final taper | B9: =INDEX('Daily Plan'!$A$2:$A$107,MATCH(A9,'Daily Plan'!$D$2:$D$107,0)) -> 46421 | C9: =SUMPRODUCT(MAX(('Daily Plan'!$D$2:$D$107=A9)*'Daily Plan'!$A$2:$A$107)) -> 46423 | D9: =COUNTIFS('Daily Plan'!$D$2:$D$107,A9) -> 3 | E9: =COUNTIFS('Daily Plan'!$D$2:$D$107,A9,'Daily Plan'!$C$2:$C$107,"Study session") -> 0 | F9: =COUNTIFS('Daily Plan'!$D$2:$D$107,A9,'Daily Plan'!$O$2:$O$107,"Complete") -> 0 | G9: =IF(D9=0,0,F9/D9) -> 0
A10: Weekly catch-up | B10: =INDEX('Daily Plan'!$A$2:$A$107,MATCH(A10,'Daily Plan'!$D$2:$D$107,0)) -> 46320 | C10: =SUMPRODUCT(MAX(('Daily Plan'!$D$2:$D$107=A10)*'Daily Plan'!$A$2:$A$107)) -> 46390 | D10: =COUNTIFS('Daily Plan'!$D$2:$D$107,A10) -> 11 | E10: =COUNTIFS('Daily Plan'!$D$2:$D$107,A10,'Daily Plan'!$C$2:$C$107,"Study session") -> 0 | F10: =COUNTIFS('Daily Plan'!$D$2:$D$107,A10,'Daily Plan'!$O$2:$O$107,"Complete") -> 0 | G10: =IF(D10=0,0,F10/D10) -> 0
A11: Total | D11: =SUM(D2:D10) -> 106 | E11: =SUM(E2:E10) -> 63 | F11: =SUM(F2:F10) -> 0 | G11: =IF(D11=0,0,F11/D11) -> 0
A13: First exam day reported for GATE 2027 (confirm your own paper date on the portal) | B13: =DATE(2027,2,6) -> 46424
A14: Days remaining from today | B14: =B13-TODAY() -> 106
A15: Priority note: CS-specific content through Computer Networks is scheduled to finish on 21 December; the final DA-only uncertainty/Machine Learning block finishes 4 January. All planned syllabus content is scheduled by 4 January, preserving the second-pass, mock/repair and final-taper date windows.

Sheet Syllabus Audit
A1: Paper | B1: Official syllabus section | C1: Planned unit(s) / date coverage | D1: Coverage status | E1: Priority treatment | F1: Official source
A2: Computer Science | B2: Engineering Mathematics | C2: Units 1–17 (completed foundation); diagnostics 25 October and 1 November | D2: Mapped to Foundation Subtopics and Official Syllabus Coverage; mastery remains unverified until scores are entered | E2: Tier 1 CSE/shared | F2: https://gate2027.iitm.ac.in/static/doc/GATE2027_Syllabus/CS_GATE2027_Syllabus.pdf
A3: Computer Science | B3: Digital Logic | C3: Units 58–59 (scheduled 4–5 December in the revised stream) | D3: Mapped; includes algebraic technique, Karnaugh map, tabular method, combinational/sequential circuits, fixed/floating point | E3: Tier 1 CSE | F3: https://gate2027.iitm.ac.in/static/doc/GATE2027_Syllabus/CS_GATE2027_Syllabus.pdf
A4: Computer Science | B4: Computer Organization and Architecture | C4: Units 60–62 (scheduled 7–10 December) | D4: Mapped; includes ISA/addressing, ALU, control-unit designs, memory hierarchy/cache, interface/interrupt/DMA, pipeline hazards | E4: Tier 1 CSE | F4: https://gate2027.iitm.ac.in/static/doc/GATE2027_Syllabus/CS_GATE2027_Syllabus.pdf
A5: Computer Science | B5: Programming and Data Structures | C5: Units 28–33, 37 (scheduled 23 October–13 November) | D5: Mapped; C and recursion; arrays, stacks, queues, linked lists, trees, BST, heaps, graphs | E5: Tier 1 CSE/shared | F5: https://gate2027.iitm.ac.in/static/doc/GATE2027_Syllabus/CS_GATE2027_Syllabus.pdf
A6: Computer Science | B6: Algorithms | C6: Units 34–39 (scheduled 30 October–9 November) | D6: Mapped; worst-case time/space, search/sort/hash, greedy, dynamic programming, divide-and-conquer, graph traversal, MST, shortest paths | E6: Tier 1 CSE/shared | F6: https://gate2027.iitm.ac.in/static/doc/GATE2027_Syllabus/CS_GATE2027_Syllabus.pdf
A7: Computer Science | B7: Theory of Computation | C7: Units 51–54 (scheduled 25 November–28 November) | D7: Mapped; finite automata/regular expressions, CFG/PDA, pumping lemma, Turing machines and undecidability | E7: Tier 1 CSE | F7: https://gate2027.iitm.ac.in/static/doc/GATE2027_Syllabus/CS_GATE2027_Syllabus.pdf
A8: Computer Science | B8: Compiler Design | C8: Units 52 and 55–57 (scheduled 26 November–3 December) | D8: Mapped; lexical analysis, parsers, syntax-directed translation, runtime environments, intermediate code and data-flow/local optimisation | E8: Tier 1 CSE | F8: https://gate2027.iitm.ac.in/static/doc/GATE2027_Syllabus/CS_GATE2027_Syllabus.pdf
A9: Computer Science | B9: Operating Systems | C9: Units 63–67 (scheduled 11–18 December) | D9: Mapped; system calls, processes/threads/IPC/synchronisation, deadlocks, CPU/I/O scheduling, memory/virtual memory and file systems | E9: Tier 1 CSE | F9: https://gate2027.iitm.ac.in/static/doc/GATE2027_Syllabus/CS_GATE2027_Syllabus.pdf
A10: Computer Science | B10: Databases | C10: Units 43–48 (scheduled 13–21 November) | D10: Mapped; ER/relational models, relational algebra/calculus/SQL, integrity constraints, normal forms, file organisation/indexing, transactions/concurrency | E10: Tier 1 CSE/shared | F10: https://gate2027.iitm.ac.in/static/doc/GATE2027_Syllabus/CS_GATE2027_Syllabus.pdf
A11: Computer Science | B11: Computer Networks | C11: Units 68–69 (scheduled 19 and 21 December); sectional test 16 January | D11: Mapped to the revised 2027 wording; sectional-test evidence determines whether a third session is necessary | E11: Tier 1 CSE | F11: https://gate2027.iitm.ac.in/static/doc/GATE2027_Syllabus/CS_GATE2027_Syllabus.pdf
A12: Data Science and Artificial Intelligence | B12: Probability and Statistics | C12: Units 12–17 (completed foundation); diagnostic 1 November | D12: Mapped; conditional PDF, distributions, conditional expectation/variance, CLT, confidence intervals and z/t/chi-squared tests explicitly listed | E12: Shared topics Tier 1; DA-only details secondary | F12: https://gate2027.iitm.ac.in/static/doc/GATE2027_Syllabus/DA_GATE2027_Syllabus.pdf
... A20: Audit boundary | B20: Coverage vs mastery | C20: See Official Syllabus Coverage sheet | D20: Official syllabus requirements have been mapped to units; this does not claim every item is already mastered. Enter diagnostics and PYQ evidence before marking a topic solid. | E20: Do not skip a mapped item | F20: https://gate2027.iitm.ac.in/exam_papers_and_syllabus

Sheet Completed Foundation
A1: Subject | B1: Source units | C1: Status | D1: Diagnostic date | E1: Diagnostic score (fraction) | F1: Needs repair in second pass?
A2: Logic (propositional and first-order) | B2: Units 1 to 2 | C2: Completed (stated by you, 23 October 2026) | D2: 46320 | F2: Not yet tested
A3: Sets, relations, lattices and functions | B3: Unit 3 | C3: Completed (stated by you, 23 October 2026) | D3: 46320 | F3: Not yet tested
A4: Combinatorics and group theory | B4: Unit 4 | C4: Completed (stated by you, 23 October 2026) | D4: 46320 | F4: Not yet tested
A5: Graph theory | B5: Unit 5 | C5: Completed (stated by you, 23 October 2026) | D5: 46320 | F5: Not yet tested
A6: Linear algebra | B6: Units 6 to 9 | C6: Completed (stated by you, 23 October 2026) | D6: 46320 | F6: Not yet tested
A7: Calculus | B7: Units 10 to 11 | C7: Completed (stated by you, 23 October 2026) | D7: 46327 | F7: Not yet tested
A8: Probability | B8: Units 12 to 15 | C8: Completed (stated by you, 23 October 2026) | D8: 46327 | F8: Not yet tested
A9: Statistics (central limit theorem, confidence intervals, hypothesis tests) | B9: Units 16 to 17 | C9: Completed (stated by you, 23 October 2026) | D9: 46327 | F9: Not yet tested
A11: Assumption: logic is counted inside the discrete mathematics you completed. If a topic was only partly covered (for example the integration part of calculus only), tell the plan and add a half-day to the first Sunday.

Sheet Foundation Subtopics
A1: Subject | B1: Subtopic | C1: Paper | D1: Source unit | E1: Status | F1: Notes
A2: Logic | B2: Propositional logic: truth tables, equivalences, normal forms, inference, resolution | C2: Both papers | D2: Unit 1 | E2: Not yet tested
A3: Logic | B3: First-order logic: quantifiers, translating sentences, unification and resolution | C3: Both papers | D3: Unit 2 | E3: Not yet tested
A4: Discrete mathematics | B4: Sets, relations, equivalence relations, partial orders, Hasse diagrams | C4: Computer Science only | D4: Unit 3 | E4: Not yet tested
A5: Discrete mathematics | B5: Lattices and functions (including counting functions) | C5: Computer Science only | D5: Unit 3 | E5: Not yet tested
A6: Combinatorics | B6: Counting, permutations and combinations | C6: Both papers | D6: Unit 4 | E6: Not yet tested | F6: Official CS and DA coverage. Continue with recurrence relations/generating functions in the next rows.
A7: Discrete mathematics | B7: Recurrence relations and generating functions | C7: Computer Science only | D7: Unit 4 | E7: Not yet tested
A8: Algebra | B8: Monoids and groups | C8: Computer Science only | D8: Unit 4 | E8: Not yet tested | F8: Official CS syllabus requirement. Lagrange's theorem is optional extra detail; do not let it displace official core.
A9: Discrete mathematics | B9: Graph terms, degree, paths, cycles, connectivity, trees | C9: Both papers | D9: Unit 5 | E9: Not yet tested
A10: Graph theory | B10: Official CS graph core: connectivity, matching and colouring | C10: Computer Science only | D10: Unit 5 | E10: Not yet tested | F10: Euler/Hamiltonian graphs and planarity are not named in the 2027 CS syllabus; keep them optional if time remains.
A11: Linear algebra | B11: Matrix properties and determinants | C11: Both papers | D11: Unit 6 | E11: Not yet tested
A12: Linear algebra | B12: Projection matrix, orthogonal matrix, idempotent matrix and partition matrices with their properties | C12: Data Science and Artificial Intelligence only | D12: Unit 6 | E12: Not yet tested | F12: Official DA wording includes each matrix type and its properties.
A13: Linear algebra | B13: Gaussian elimination, solutions of linear systems, rank and nullity | C13: Both papers | D13: Unit 7 | E13: Not yet tested
A14: Linear algebra | B14: Lower-upper (LU) decomposition | C14: Both papers | D14: Unit 7 | E14: Not yet tested
A15: Linear algebra | B15: Vector spaces, subspaces, linear independence, basis and dimension | C15: Both papers | D15: Unit 8 | E15: Not yet tested
A16: Linear algebra | B16: Projections | C16: Data Science and Artificial Intelligence only | D16: Unit 8 | E16: Not yet tested
A17: Linear algebra | B17: Eigenvalues and eigenvectors | C17: Both papers | D17: Unit 9 | E17: Not yet tested | F17: Cayley–Hamilton theorem is not named in either official 2027 syllabus; treat it as optional enrichment, not a must-master topic.
A18: Linear algebra | B18: Quadratic forms | C18: Data Science and Artificial Intelligence only | D18: Unit 9 | E18: Not yet tested
A19: Linear algebra | B19: Singular value decomposition | C19: Data Science and Artificial Intelligence only | D19: Unit 9 | E19: Not yet tested
A20: Calculus | B20: Functions of a single variable, limits, continuity and differentiability | C20: Both papers | D20: Unit 10 | E20: Not yet tested | F20: L'Hôpital's rule is not explicitly named in the 2027 syllabi; don't let it displace mean value theorem or integration for CS.
A21: Calculus | B21: Mean value theorems | C21: Computer Science only | D21: Unit 10 | E21: Not yet tested
A22: Calculus | B22: Definite and indefinite integration | C22: Computer Science only | D22: Unit 10 | E22: Not yet tested
A23: Calculus | B23: Maxima and minima, single-variable optimization | C23: Both papers | D23: Unit 11 | E23: Not yet tested
A24: Calculus | B24: Taylor and Maclaurin series | C24: Data Science and Artificial Intelligence only | D24: Unit 11 | E24: Not yet tested
A25: Probability | B25: Probability axioms, sample spaces and events; counting, conditional probability, independence, mutually exclusive events and Bayes' theorem | C25: Both papers | D25: Unit 12 | E25: Not yet tested | F25: Use CSE-level probability coverage plus DA-specific probability PYQs.
A26: Probability | B26: Probability mass function, probability density function, cumulative distribution function | C26: Both papers | D26: Unit 13 | E26: Not yet tested
A27: Probability | B27: Expectation, variance, mean, median, mode, standard deviation | C27: Both papers | D27: Unit 13 | E27: Not yet tested
A28: Probability | B28: Conditional expectation and conditional variance | C28: Data Science and Artificial Intelligence only | D28: Unit 13 | E28: Not yet tested
A29: Probability | B29: Uniform, Bernoulli, binomial and Poisson distributions | C29: Both papers | D29: Unit 14 | E29: Not yet tested
A30: Probability | B30: Exponential, normal and standard normal distributions | C30: Both papers | D30: Unit 15 | E30: Not yet tested
A31: Probability | B31: Joint, marginal and conditional distributions, including conditional probability density functions for DA | C31: Data Science and Artificial Intelligence only | D31: Unit 15 | E31: Not yet tested | F31: Official DA syllabus explicitly includes marginal, conditional and joint probabilities and conditional PDF.
A32: Probability | B32: Covariance and correlation | C32: Data Science and Artificial Intelligence only | D32: Unit 15 | E32: Not yet tested
A33: Statistics | B33: Central limit theorem | C33: Data Science and Artificial Intelligence only | D33: Unit 16 | E33: Not yet tested
A34: Statistics | B34: Student's t and chi-squared distributions | C34: Data Science and Artificial Intelligence only | D34: Unit 16 | E34: Not yet tested
A35: Statistics | B35: Confidence intervals | C35: Data Science and Artificial Intelligence only | D35: Unit 16 | E35: Not yet tested
A36: Statistics | B36: Null and alternate hypotheses, z-test, t-test, chi-squared test | C36: Data Science and Artificial Intelligence only | D36: Unit 17 | E36: Not yet tested
A38: Subtopics tested as solid | E38: =COUNTIF(E2:E36,"Solid") -> 0
A39: Subtopics needing revision or not covered (put these on the January second-pass list) | E39: =COUNTIF(E2:E36,"Needs revision")+COUNTIF(E2:E36,"Not covered") -> 0
A40: Subtopics not yet tested | E40: =COUNTIF(E2:E36,"Not yet tested") -> 35
A42: Source: Official GATE 2027 syllabi (IIT Madras). These entries are mapped to syllabus wording, but a 'Not yet tested' status means mastery is not asserted. CSE PDF: https://gate2027.iitm.ac.in/static/doc/GATE2027_Syllabus/CS_GATE2027_Syllabus.pdf | DA PDF: https://gate2027.iitm.ac.in/static/doc/GATE2027_Syllabus/DA_GATE2027_Syllabus.pdf. Use the 25 Oct and 1 Nov diagnostics to record actual evidence.

Sheet Subject Checklists
A1: Subject | B1: Subtopic | C1: Unit | D1: First scheduled date | E1: Priority | F1: Status | G1: Evidence or previous-year question score | H1: Notes
A2: Operating Systems | B2: System calls, process states, process control block, context switching | C2: Unit 63 | D2: =IFERROR(INDEX('Daily Plan'!$A$2:$A$107,MATCH(C2,'Daily Plan'!$E$2:$E$107,0)),"") -> 46367 | E2: High | F2: Not yet checked
A3: Operating Systems | B3: Threads (user and kernel) | C3: Unit 63 | D3: =IFERROR(INDEX('Daily Plan'!$A$2:$A$107,MATCH(C3,'Daily Plan'!$E$2:$E$107,0)),"") -> 46367 | E3: High | F3: Not yet checked
A4: Operating Systems | B4: Central processing unit scheduling: first-come first-served, shortest job first, shortest remaining time first, round robin, priority | C4: Unit 63 | D4: =IFERROR(INDEX('Daily Plan'!$A$2:$A$107,MATCH(C4,'Daily Plan'!$E$2:$E$107,0)),"") -> 46367 | E4: High | F4: Not yet checked
A5: Operating Systems | B5: Critical section problem, Peterson's solution, mutex, semaphores, classical problems, inter-process communication | C5: Unit 64 | D5: =IFERROR(INDEX('Daily Plan'!$A$2:$A$107,MATCH(C5,'Daily Plan'!$E$2:$E$107,0)),"") -> 46368 | E5: High | F5: Not yet checked
A6: Operating Systems | B6: Deadlocks: conditions, resource allocation graphs, prevention, Banker's algorithm, detection, recovery | C6: Unit 65 | D6: =IFERROR(INDEX('Daily Plan'!$A$2:$A$107,MATCH(C6,'Daily Plan'!$E$2:$E$107,0)),"") -> 46371 | E6: High | F6: Not yet checked
A7: Operating Systems | B7: Paging, multi-level page tables, translation lookaside buffer, segmentation | C7: Unit 66 | D7: =IFERROR(INDEX('Daily Plan'!$A$2:$A$107,MATCH(C7,'Daily Plan'!$E$2:$E$107,0)),"") -> 46372 | E7: High | F7: Not yet checked
A8: Operating Systems | B8: Demand paging, page replacement, thrashing | C8: Unit 66 | D8: =IFERROR(INDEX('Daily Plan'!$A$2:$A$107,MATCH(C8,'Daily Plan'!$E$2:$E$107,0)),"") -> 46372 | E8: High | F8: Not yet checked
A9: Operating Systems | B9: File systems, file allocation methods, free-space management and I/O scheduling scope | C9: Unit 67 | E9: High | F9: Not yet checked | H9: Official CS syllabus explicitly includes CPU and I/O scheduling; the scheduled session emphasises disk/I/O scheduling.
A10: Operating Systems | B10: Disk scheduling: first-come first-served, shortest seek time first, SCAN, C-SCAN and LOOK | C10: Unit 67 | E10: High | F10: Not yet checked
A11: Databases | B11: Entity-relationship model, relational model, keys, integrity constraints | C11: Unit 43 | D11: =IFERROR(INDEX('Daily Plan'!$A$2:$A$107,MATCH(C11,'Daily Plan'!$E$2:$E$107,0)),"") -> 46339 | E11: High | F11: Not yet checked
A12: Databases | B12: Relational algebra and tuple relational calculus | C12: Unit 44 | D12: =IFERROR(INDEX('Daily Plan'!$A$2:$A$107,MATCH(C12,'Daily Plan'!$E$2:$E$107,0)),"") -> 46340 | E12: High | F12: Not yet checked
A13: Databases | B13: Structured Query Language: joins, grouping, aggregation, nested and correlated subqueries, views | C13: Unit 45 | D13: =IFERROR(INDEX('Daily Plan'!$A$2:$A$107,MATCH(C13,'Daily Plan'!$E$2:$E$107,0)),"") -> 46342 | E13: High | F13: Not yet checked
A14: Databases | B14: Functional dependencies, attribute closure, minimal cover | C14: Unit 46 | D14: =IFERROR(INDEX('Daily Plan'!$A$2:$A$107,MATCH(C14,'Daily Plan'!$E$2:$E$107,0)),"") -> 46344 | E14: High | F14: Not yet checked
A15: Databases | B15: Normal forms through Boyce-Codd normal form, lossless join, dependency preservation | C15: Unit 46 | D15: =IFERROR(INDEX('Daily Plan'!$A$2:$A$107,MATCH(C15,'Daily Plan'!$E$2:$E$107,0)),"") -> 46344 | E15: High | F15: Not yet checked
A16: Databases | B16: File organization, indexing, B-trees and B+ trees | C16: Unit 47 | D16: =IFERROR(INDEX('Daily Plan'!$A$2:$A$107,MATCH(C16,'Daily Plan'!$E$2:$E$107,0)),"") -> 46346 | E16: High | F16: Not yet checked
A17: Databases | B17: Transactions, atomicity, consistency, isolation, durability, serializability, recoverability | C17: Unit 48 | D17: =IFERROR(INDEX('Daily Plan'!$A$2:$A$107,MATCH(C17,'Daily Plan'!$E$2:$E$107,0)),"") -> 46347 | E17: High | F17: Not yet checked
A18: Databases | B18: Concurrency control: two-phase locking, timestamp ordering, deadlock and recovery | C18: Unit 48 | D18: =IFERROR(INDEX('Daily Plan'!$A$2:$A$107,MATCH(C18,'Daily Plan'!$E$2:$E$107,0)),"") -> 46347 | E18: High | F18: Not yet checked
A19: Databases | B19: Data preparation: data types; transformation including normalization, discretization, sampling and compression (DA only) | C19: Unit 49 | E19: Medium | F19: Not yet checked
A20: Databases | B20: Multidimensional models, star and snowflake schemas, hierarchies, online analytical processing, measures (Data Science and Artificial Intelligence only) | C20: Unit 50 | D20: =IFERROR(INDEX('Daily Plan'!$A$2:$A$107,MATCH(C20,'Daily Plan'!$E$2:$E$107,0)),"") -> 46350 | E20: Medium | F20: Not yet checked
A21: Theory of Computation | B21: Regular expressions, deterministic and nondeterministic finite automata, minimization, Arden's theorem | C21: Unit 51 | D21: =IFERROR(INDEX('Daily Plan'!$A$2:$A$107,MATCH(C21,'Daily Plan'!$E$2:$E$107,0)),"") -> 46351 | E21: High | F21: Not yet checked
A22: Theory of Computation | B22: Regular language closure properties and pumping lemma | C22: Unit 52 | D22: =IFERROR(INDEX('Daily Plan'!$A$2:$A$107,MATCH(C22,'Daily Plan'!$E$2:$E$107,0)),"") -> 46352 | E22: High | F22: Not yet checked
A23: Theory of Computation | B23: Context-free grammars, ambiguity, Chomsky normal form | C23: Unit 53 | D23: =IFERROR(INDEX('Daily Plan'!$A$2:$A$107,MATCH(C23,'Daily Plan'!$E$2:$E$107,0)),"") -> 46353 | E23: High | F23: Not yet checked
A24: Theory of Computation | B24: Pushdown automata, context-free language closure properties, pumping lemma for context-free languages | C24: Unit 53 | D24: =IFERROR(INDEX('Daily Plan'!$A$2:$A$107,MATCH(C24,'Daily Plan'!$E$2:$E$107,0)),"") -> 46353 | E24: High | F24: Not yet checked
A25: Theory of Computation | B25: Turing machines, recursive and recursively enumerable languages | C25: Unit 54 | D25: =IFERROR(INDEX('Daily Plan'!$A$2:$A$107,MATCH(C25,'Daily Plan'!$E$2:$E$107,0)),"") -> 46354 | E25: High | F25: Not yet checked
A26: Theory of Computation | B26: Undecidability, including the halting problem; use reductions/examples as supporting practice | C26: Unit 54 | E26: High | F26: Not yet checked | H26: Rice's theorem is not explicitly named in the 2027 CS syllabus; use it as an example only if time remains.
A27: Compiler Design | B27: Lexical analysis: tokens, lexemes, scanner | C27: Unit 52 | D27: =IFERROR(INDEX('Daily Plan'!$A$2:$A$107,MATCH(C27,'Daily Plan'!$E$2:$E$107,0)),"") -> 46352 | E27: High | F27: Not yet checked
A28: Compiler Design | B28: Parsing: FIRST and FOLLOW sets, LL(1), LR(0), SLR(1), CLR(1), LALR(1) | C28: Unit 55 | D28: =IFERROR(INDEX('Daily Plan'!$A$2:$A$107,MATCH(C28,'Daily Plan'!$E$2:$E$107,0)),"") -> 46356 | E28: High | F28: Not yet checked
A29: Compiler Design | B29: Syntax-directed translation: S-attributed and L-attributed definitions | C29: Unit 56 | D29: =IFERROR(INDEX('Daily Plan'!$A$2:$A$107,MATCH(C29,'Daily Plan'!$E$2:$E$107,0)),"") -> 46358 | E29: High | F29: Not yet checked
A30: Compiler Design | B30: Runtime environments and activation records | C30: Unit 56 | D30: =IFERROR(INDEX('Daily Plan'!$A$2:$A$107,MATCH(C30,'Daily Plan'!$E$2:$E$107,0)),"") -> 46358 | E30: Medium | F30: Not yet checked
A31: Compiler Design | B31: Intermediate code: three-address code | C31: Unit 56 | D31: =IFERROR(INDEX('Daily Plan'!$A$2:$A$107,MATCH(C31,'Daily Plan'!$E$2:$E$107,0)),"") -> 46358 | E31: High | F31: Not yet checked
A32: Compiler Design | B32: Basic blocks, control flow graphs, local optimization | C32: Unit 57 | D32: =IFERROR(INDEX('Daily Plan'!$A$2:$A$107,MATCH(C32,'Daily Plan'!$E$2:$E$107,0)),"") -> 46359 | E32: High | F32: Not yet checked
A33: Compiler Design | B33: Constant propagation, liveness analysis, common subexpression elimination | C33: Unit 57 | D33: =IFERROR(INDEX('Daily Plan'!$A$2:$A$107,MATCH(C33,'Daily Plan'!$E$2:$E$107,0)),"") -> 46359 | E33: High | F33: Not yet checked
A34: Digital Logic | B34: Boolean algebra, logic gates and algebraic minimization technique | C34: Unit 58 | E34: High | F34: Not yet checked
A35: Digital Logic | B35: Karnaugh maps and the tabular (Quine-McCluskey) method | C35: Unit 58 | D35: =IFERROR(INDEX('Daily Plan'!$A$2:$A$107,MATCH(C35,'Daily Plan'!$E$2:$E$107,0)),"") -> 46360 | E35: High | F35: Not yet checked
A36: Digital Logic | B36: Combinational circuits: multiplexers, decoders, adders | C36: Unit 59 | D36: =IFERROR(INDEX('Daily Plan'!$A$2:$A$107,MATCH(C36,'Daily Plan'!$E$2:$E$107,0)),"") -> 46361 | E36: High | F36: Not yet checked
A37: Digital Logic | B37: Sequential circuits: latches, flip-flops, counters, finite state machines | C37: Unit 59 | D37: =IFERROR(INDEX('Daily Plan'!$A$2:$A$107,MATCH(C37,'Daily Plan'!$E$2:$E$107,0)),"") -> 46361 | E37: High | F37: Not yet checked
A38: Digital Logic | B38: Number representation and arithmetic: two's complement, fixed-point, floating-point (IEEE 754) | C38: Unit 59 | D38: =IFERROR(INDEX('Daily Plan'!$A$2:$A$107,MATCH(C38,'Daily Plan'!$E$2:$E$107,0)),"") -> 46361 | E38: High | F38: Not yet checked
A39: Computer Organization and Architecture | B39: Instruction set, addressing modes | C39: Unit 60 | D39: =IFERROR(INDEX('Daily Plan'!$A$2:$A$107,MATCH(C39,'Daily Plan'!$E$2:$E$107,0)),"") -> 46363 | E39: High | F39: Not yet checked
A40: Computer Organization and Architecture | B40: Arithmetic logic unit and datapath | C40: Unit 60 | D40: =IFERROR(INDEX('Daily Plan'!$A$2:$A$107,MATCH(C40,'Daily Plan'!$E$2:$E$107,0)),"") -> 46363 | E40: High | F40: Not yet checked
...

Sheet Question Tracker
A1: Date | B1: Paper | C1: Year | D1: Topic | E1: Questions attempted | F1: Correct | G1: Accuracy (fraction) | H1: Time spent (minutes) | I1: Error category | J1: Re-solve date | K1: Notes
A2: 46321 | B2: Computer Science | C2: 2024 | D2: Example row: graph algorithms (delete this row) | E2: 20 | F2: 14 | G2: =IF(E2>0,F2/E2,"") -> 0.7 | H2: 95 | I2: Concept | J2: 46328 | K2: Review shortest-path questions again
G3: =IF(E3>0,F3/E3,"")
G4: =IF(E4>0,F4/E4,"")
G5: =IF(E5>0,F5/E5,"")
G6: =IF(E6>0,F6/E6,"")
G7: =IF(E7>0,F7/E7,"")
G8: =IF(E8>0,F8/E8,"")
G9: =IF(E9>0,F9/E9,"")
G10: =IF(E10>0,F10/E10,"")
G11: =IF(E11>0,F11/E11,"")
G12: =IF(E12>0,F12/E12,"")
G13: =IF(E13>0,F13/E13,"")
G14: =IF(E14>0,F14/E14,"")
... G41: =IF(E41>0,F41/E41,"")

Sheet Change Log
A1: Change | B1: Details
A2: CSE-first study order | B2: Re-sequenced the existing 62 study sessions: programming/data structures/algorithms first; AI search follows graph algorithms; database core precedes warehousing; TOC/compiler and CSE systems next; DA-only uncertainty and Machine Learning are last.
A3: Priority tiers | B3: All CSE-only and genuinely shared study sessions are Tier 1 — CSE/shared must master. DA-only sessions are Tier 2 — DA secondary coverage. DA content is still required; the rule limits its daily time so it cannot displace CSE practice.
A4: Dates and sessions preserved | B4: The calendar dates remain 24 October 2026–5 February 2027; all original phase date windows are unchanged; exactly 62 study-session slots remain.
A5: Official syllabus audit | B5: Added Official Syllabus Coverage with CS and DA requirements mapped to units, dates, priority and the official PDF URL. Syllabus mapping is verified against the official syllabus text; mastery is not claimed until diagnostics/PYQs are entered.
A6: Foundation checklist | B6: Updated Foundation Subtopics wording to include probability axioms/events/mutual exclusivity and conditional PDF and to mark optional topics not named in the 2027 syllabus as optional.
A7: CS subtopic checklist | B7: Updated subject checklist descriptions to explicitly include minimization technique, memory interfacing/hierarchy, I/O scheduling and data compression.
A8: DA official papers | B8: Moved DA 2024/2025/2026 timed paper attempts to 10/17/24 January, after all DA-specific content ends on 4 January; converted generic DA full mocks in the mock runway to targeted sectionals.
A9: Networks gate | B9: Kept the 16 January Networks sectional test and explicit <70% / material-gap / Unit 69-incomplete trigger for borrowing a repair day for a third session.
A10: Dynamic scoping wording | B10: Removed dynamic scoping as a C feature in Unit 29. C uses lexical/static scope; dynamic scoping is not an explicit 2027 CS syllabus requirement.
A11: Formula checks | B11: Restored the Unit complete formula after schedule re-sequencing and set the countdown cell to a number format so days remaining display numerically.
A12: Source | B12: Master source: GATE_2027_Final_Day_by_Day_Plan_Master.xlsx. Use this final workbook as the single master; retain other copies only as references.
A13: Plan start moved to 23 Oct 2026 | B13: Added a 23 Oct 2026 (today) row and split Unit 28 into Session A (C) on 23 Oct and Session B (Python) on 24 Oct. All dates, units and sessions from 25 Oct onward are unchanged; Units 1-17 (Completed Foundation) and all completion fields are untouched. Study-session slots: 63.

Sheet Official Syllabus Coverage
A1: Paper | B1: Official syllabus area | C1: Requirement to verify | D1: Planned unit(s) | E1: Planned date(s) | F1: Priority treatment | G1: Coverage mapping status | H1: Official source URL | I1: Notes / practice evidence
A2: Computer Science | B2: Engineering Mathematics — Discrete Mathematics | C2: Propositional and first-order logic; sets, relations, functions, partial orders and lattices; monoids and groups; graphs (connectivity, matching, colouring); counting, recurrence relations and generating functions. | D2: Units 1, 2, 3, 4, 5 | E2: Completed foundation; diagnostics 25 Oct and 1 Nov 2026 | F2: Tier 1 — CSE/shared must master | G2: Mapped to planned units; mastery unverified | H2: https://gate2027.iitm.ac.in/static/doc/GATE2027_Syllabus/CS_GATE2027_Syllabus.pdf | I2: Official core mapped to completed foundation. Lagrange's theorem, Euler/Hamiltonian graph details and planarity are not named as must-cover 2027 items; keep optional.
A3: Computer Science | B3: Engineering Mathematics — Linear Algebra | C3: Matrices, determinants, systems of linear equations, eigenvalues/eigenvectors and LU decomposition. | D3: Units 6, 7, 8, 9 | E3: Completed foundation; diagnostics 25 Oct and 1 Nov 2026 | F3: Tier 1 — CSE/shared must master | G3: Mapped to planned units; mastery unverified | H3: https://gate2027.iitm.ac.in/static/doc/GATE2027_Syllabus/CS_GATE2027_Syllabus.pdf | I3: DA-only extensions such as vector spaces, quadratic forms and SVD are in the foundation checklist but are not required by the CS syllabus line.
A4: Computer Science | B4: Engineering Mathematics — Calculus | C4: Limits, continuity and differentiability; maxima and minima; mean value theorem; integration. | D4: Units 10, 11 | E4: Completed foundation; diagnostics 25 Oct and 1 Nov 2026 | F4: Tier 1 — CSE/shared must master | G4: Mapped to planned units; mastery unverified | H4: https://gate2027.iitm.ac.in/static/doc/GATE2027_Syllabus/CS_GATE2027_Syllabus.pdf | I4: Mean value theorem and integration are explicitly called out in the official CS PDF.
A5: Computer Science | B5: Engineering Mathematics — Probability and Statistics | C5: Random variables; uniform, normal, exponential, Poisson and binomial distributions; mean, median, mode, standard deviation; conditional probability and Bayes' theorem. | D5: Units 12, 13, 14, 15 | E5: Completed foundation; diagnostics 25 Oct and 1 Nov 2026 | F5: Tier 1 — CSE/shared must master | G5: Mapped to planned units; mastery unverified | H5: https://gate2027.iitm.ac.in/static/doc/GATE2027_Syllabus/CS_GATE2027_Syllabus.pdf | I5: Use CSE PYQs first; keep DA's more detailed test/distribution subtopics in the DA-specific foundation checklist.
A6: Computer Science | B6: Digital Logic — minimization | C6: Boolean algebra and minimization by algebraic technique, Karnaugh map and tabular method. | D6: Units 58 | E6: Unit 58: 04 Dec 2026 | F6: Tier 1 — CSE primary | G6: Mapped to planned units; mastery unverified | H6: https://gate2027.iitm.ac.in/static/doc/GATE2027_Syllabus/CS_GATE2027_Syllabus.pdf | I6: Unit 58 description explicitly includes all three minimization methods.
A7: Computer Science | B7: Digital Logic — circuits and number representation | C7: Design of combinational and sequential circuits; number representation and arithmetic in fixed-point and floating-point formats. | D7: Units 59 | E7: Unit 59: 05 Dec 2026 | F7: Tier 1 — CSE primary | G7: Mapped to planned units; mastery unverified | H7: https://gate2027.iitm.ac.in/static/doc/GATE2027_Syllabus/CS_GATE2027_Syllabus.pdf | I7: Unit 59 mapped; test logic design and representation questions separately.
A8: Computer Science | B8: Computer Organization and Architecture — instruction/datapath/control | C8: Instruction set and addressing modes; ALU design; hardwired and microprogrammed control-unit design. | D8: Units 60 | E8: Unit 60: 07 Dec 2026 | F8: Tier 1 — CSE primary | G8: Mapped to planned units; mastery unverified | H8: https://gate2027.iitm.ac.in/static/doc/GATE2027_Syllabus/CS_GATE2027_Syllabus.pdf | I8: Unit 60 mapped.
A9: Computer Science | B9: Computer Organization and Architecture — memory/I/O/pipeline | C9: Memory interfacing and hierarchy performance; cache memory mapping; I/O interface, interrupts and DMA; instruction pipelining and pipeline hazards. | D9: Units 61, 62 | E9: Unit 61: 08 Dec 2026; Unit 62: 09 Dec 2026 to 10 Dec 2026 | F9: Tier 1 — CSE primary | G9: Mapped to planned units; mastery unverified | H9: https://gate2027.iitm.ac.in/static/doc/GATE2027_Syllabus/CS_GATE2027_Syllabus.pdf | I9: Unit 62 now names memory interfacing/hierarchy and I/O interface explicitly; Unit 61 covers hazards.
A10: Computer Science | B10: Programming and Data Structures | C10: Programming in C and recursion; arrays, stacks, queues, linked lists, trees, BSTs, binary heaps and graphs. | D10: Units 28, 29, 30, 31, 32, 33, 37 | E10: Unit 28: 23 Oct 2026 to 24 Oct 2026; Unit 29: 26 Oct 2026; Unit 30: 27 Oct 2026; Unit 31: 28 Oct 2026; Unit 32: 29 Oct 2026; Unit 33: 30 Oct 2026; Unit 37: 04 Nov 2026 to 05 Nov 2026 | F10: Tier 1 — CSE/shared must master | G10: Mapped to planned units; mastery unverified | H10: https://gate2027.iitm.ac.in/static/doc/GATE2027_Syllabus/CS_GATE2027_Syllabus.pdf | I10: Unit 28 includes C recursion and Python basics for DA; Unit 29 does C tracing and Python collection tracing. C itself uses static/lexical scope; dynamic scoping is not a C feature.
A11: Computer Science | B11: Algorithms — search, sort, hashing and complexity | C11: Searching, sorting and hashing; asymptotic worst-case time and space complexity. | D11: Units 33, 34, 35 | E11: Unit 33: 30 Oct 2026; Unit 34: 31 Oct 2026; Unit 35: 02 Nov 2026 | F11: Tier 1 — CSE/shared must master | G11: Mapped to planned units; mastery unverified | H11: https://gate2027.iitm.ac.in/static/doc/GATE2027_Syllabus/CS_GATE2027_Syllabus.pdf | I11: Unit 33 covers hashing; Unit 34 complexity; Unit 35 search/sorting.
A12: Computer Science | B12: Algorithms — design techniques | C12: Greedy algorithms, dynamic programming, divide-and-conquer, graph traversals, minimum spanning trees and shortest paths. | D12: Units 36, 37, 38, 39 | E12: Unit 36: 03 Nov 2026; Unit 37: 04 Nov 2026 to 05 Nov 2026; Unit 38: 06 Nov 2026; Unit 39: 07 Nov 2026 to 09 Nov 2026 | F12: Tier 1 — CSE/shared must master | G12: Mapped to planned units; mastery unverified | H12: https://gate2027.iitm.ac.in/static/doc/GATE2027_Syllabus/CS_GATE2027_Syllabus.pdf | I12: Greedy/MST and dynamic programming receive separate sessions; graph paths are split into two sessions.
... A39: Both papers | B39: General Aptitude and exam pattern | C39: General Aptitude is 15 marks in each paper; GATE papers also use MCQ, MSQ and NAT questions and assess recall, comprehension, application and analysis/synthesis. | D39: All dates / General Aptitude | E39: Daily through 5 Feb 2027 | F39: Daily baseline | G39: Mapped to planned units; mastery unverified | H39: https://gate2027.iitm.ac.in/exam_papers_and_syllabus | I39: Daily 20–30 minutes; practise CSE and DA question styles separately.

Sheet Priority & Daily Routine
A1: Purpose | B1: CSE primary, DA secondary: how to follow this calendar
A2: Priority | B2: Tier 1 — CSE/shared must master. CSE-only topics and topics genuinely common to both papers get the strongest practice and repair priority.
A3: Priority | B3: Tier 2 — DA secondary coverage. DA-only topics must still be completed, but new-content time is capped so they do not displace CSE practice or repair.
A4: Calendar integrity | B4: The date rows (23 Oct added as Session A of Unit 28; 24 Oct onward unchanged)s and other study-session slots are unchanged (63 slots in total). Phase date windows are unchanged. Topics have been re-sequenced inside those slots to put CSE/shared content first while preserving topic prerequisites.
A6: Day type | B6: Main work | C6: Question practice | D6: General Aptitude / revision | E6: Total target | F6: Completion rule
A7: CSE-only topic day | B7: 3.5–4 h concepts, examples and derivations | C7: 1.5–2 h CSE previous-year questions; analyse all wrong/guessed answers | D7: 20–30 min General Aptitude; 30–45 min spaced revision; 20 min foundation recall; 15–20 min mistake log | E7: 6.5–8 h | F7: Do not move on until you can solve representative questions without notes.
A8: Shared CSE + DA topic day | B8: 3–4 h learn once, with one coherent topic stream | C8: 1.5–2 h CSE PYQs first; then 30–45 min DA-style variants (Python/NAT/MSQ/multi-step) only where relevant | D8: 20–30 min General Aptitude; 30–45 min spaced revision; 20 min foundation recall; 15–20 min mistake log | E8: 6.5–8 h | F8: Learn common concept once; practise the two papers' question styles separately.
A9: DA-only topic day | B9: 3–3.5 h DA concepts and worked examples | C9: 60–90 min DA PYQs; then 1.5 h CSE-primary recall/PYQs from completed Units 1–17 | D9: 20–30 min General Aptitude; 30 min spaced revision; 15–20 min mistake log | E9: 6–7.5 h | F9: Complete the DA syllabus, but do not let DA-only new content consume the whole day.
A10: Sunday catch-up | B10: No new topic. Finish only the current incomplete chapter/subtopics; keep sequence intact. | C10: 60–90 min sectional quiz when topics are covered; analyse errors | D10: General Aptitude, formula recall and mistake log | E10: 3.5–6 h | F10: No unrelated new chapters. Official-paper Sundays are explicit exceptions.
A11: Official paper day | B11: Attempt the authentic paper for 180 minutes under exam conditions | C11: Spend 1.5–2.5 h on same-day analysis: wrong, guessed, unattempted, time sink and topic | D11: Short GA/recovery only if time allows | E11: 6–7 h | F11: Use only authentic paper/answer key. Paper attempts are planning targets, not official appointments.
A12: Repair day | B12: Target the top 1–3 repeated mistakes from the last test | C12: Re-solve wrong questions without solutions; then take a short retest | D12: 20–30 min General Aptitude; spaced review | E12: 5–7 h | F12: Repair known weaknesses; don't start an unrelated chapter.
A13: Minimum viable day | B13: 2 h concept and worked examples | C13: 1 h high-priority questions | D13: 30 min spaced revision; include 15–20 min General Aptitude if possible | E13: 3.5 h | F13: Preserve continuity. Carry remaining questions to the next catch-up slot.
A15: Sequence rules | B15: 1. Finish each split chapter's Session A before Session B; 2. shared topics are learned once; 3. CSE PYQs come first on shared topics; 4. DA-only practice never replaces CSE repair; 5. diagnose score below 70% and assign a repair.
A16: DA paper plan | B16: 10 Jan: DA 2024; 17 Jan: DA 2025; 24 Jan: DA 2026. Each occurs after the last DA-specific content block ends on 4 Jan. Verify paper and key authenticity before attempting.
A17: Networks gate | B17: 16 Jan: timed Networks sectional test. Add a third Networks session only if score <70%, the test shows a material topic gap, or Unit 69 is incomplete. Borrow from 18 or 19 Jan; do not add a date.
A18: Official syllabus sources | B18: https://gate2027.iitm.ac.in/static/doc/GATE2027_Syllabus/CS_GATE2027_Syllabus.pdf
A19: Official syllabus sources | B19: https://gate2027.iitm.ac.in/static/doc/GATE2027_Syllabus/DA_GATE2027_Syllabus.pdf
A20: Official GATE 2027 syllabus page / paper pattern | B20: https://gate2027.iitm.ac.in/exam_papers_and_syllabus
